Workbook

Sheet Paste here
A1: Sl. No. | B1: Timestamp | C1: Email Address | D1: Date of Exam | E1: No. of sessions | F1: Degree | G1: Subject Type | H1: Subject Code | I1: Subject Name | J1: Department of Candidate | K1: Semester | L1: Ext. Examiner type | M1: No. of Cands. Regd. | N1: No. of Cands. Examined | O1: Title of External Examiner | P1: Name of External Examiner | Q1: Phone No. of External Examiner | R1: Department of External Examiner | S1: Designation of External Examiner | T1: College of External Examiner | U1: Bank Account No. (External Examiner) | V1: Bank Name (External Examiner) | W1: IFSC Code (External Examiner) | X1: Bank Branch (External Examiner) | Y1: Title of Internal Examiner | Z1: Name of Internal Examiner | AA1: Phone No. of Internal Examiner | AB1: Department of Internal Examiner | AC1: Designation of Internal Examiner | AD1: Bank Account No. (Internal Examiner) | AE1: Bank Name (Internal Examiner) | AF1: IFSC Code (Internal Examiner) | AG1: Bank Branch (Internal Examiner) | AH1: Title of Skilled Asst. | AI1: Name of Skilled Asst.(Initial at End) | AJ1: Phone No. of Skilled Asst. | AK1: Department of Skilled Asst. | AL1: Designation of Skilled Asst. | AM1: Bank Account No. (Skilled Asst.) | AN1: Bank Name (Skilled Asst.) | AO1: IFSC Code (Skilled Asst.) | AP1: Bank Branch (Skilled Asst.) | AQ1: Title of Lab Technician | AR1: Name of Lab Technician (Initial at End) | AS1: Phone No. of Lab Technician | AT1: Department of Lab Technician | AU1: Bank Account No. (Lab Technician) | AV1: Bank Name (Lab Technician) | AW1: IFSC Code of (Lab Technician) | AX1: Bank Branch (Lab Technician)
B2: 46179.541 | C2: kasthurirenganp.cse@krce.ac.in | D2: 06.06.2026 | E2: Only FN | F2: UG | G2: TCPL | H2: GEA1107 | I2: C PROGRAMMING | J2: ECE | K2: I | L2: Regular Lab | M2: 23 | N2: 22 | O2: Mrs. | P2: Ranjani U | Q2: 8270981412 | R2: AIDS | S2: Assistant Professor | T2: MAM SCHOOL OF ENGINEERING (8121) | U2: 6658000400036837 | V2: Punjab National Bank | W2: PUNB0665800 | X2: SIRUGANUR | Y2: Mr. | Z2: KASTHURI RENGAN P | AA2: 9842612131 | AB2: CSE | AC2: Assistant Professor | AD2: 913010015846824 | AE2: Axis Bank | AF2: UTIB0001746 | AG2: KOTTUR | AH2: Mrs. | AI2: Surya G | AJ2: 8220915957 | AK2: CSE | AL2: Assistant Professor | AM2: 609301501667 | AN2: ICICI Bank | AO2: ICIC0006093 | AP2: JAWAHAR STREET NACHANDUPATTI | AQ2: N/A | AR2: NA | AS2: 0 | AT2: N/A | AU2: NA
A35: L40
A36: L41
A37: L42
A38: L43
A39: L44
A40: L45
A41: L46
A42: L47
A43: L48
A44: L49
A45: L50
A46: L51
... A54: L59

Sheet Mail merge
A1: Sl. No. | B1: Degree | C1: Department of Candidate | D1: Semester | E1: Subject Code | F1: Subject Name | G1: Subject Type | H1: Date of Exam | I1: Session | K1: Title of External Examiner | L1: Name of External Examiner | M1: Designation of External Examiner | N1: Department of External Examiner | O1: College of External Examiner | P1: Distance (Km) | Q1: Phone No. of External Examiner | R1: No. of Cands. Regd. | S1: No. of Cands. Examined | T1: Claim Amount | U1: TA | V1: DA | W1: TOTAL | X1: Account No. of External Examiner | Y1: Bank Name of External Examiner | Z1: IFSC Code of External Examiner | AA1: Branch of External Examiner | AB1: Amount in words Ext. Examiner | AD1: Title of Internal Examiner | AE1: Name of Internal Examiner | AF1: Designation of Internal Examiner | AG1: Department of Internal Examiner | AH1: College of Internal Examiner | AI1: Phone No. of Internal Examiner | AJ1: No. of Cands. Regd. | AK1: No. of Cands. Examined | AL1: TOTAL | AM1: Account No. of Internal Examiner | AN1: Bank Name of Internal Examiner | AO1: IFSC Code of Internal Examiner | AP1: Branch of Internal Examiner | AQ1: Amount in words Int. Examiner | AS1: Title of Skilled Asst. | AT1: Name of Skilled Asst. | AU1: Designation of Skilled Asst. | AV1: Department of Skilled Asst. | AW1: College of Skilled Asst. | AX1: Phone No. of Skilled Asst. | AY1: No. of Cands. Regd. | AZ1: No. of Cands. Examined | BA1: Total amount | BB1: Account No. of Skilled Asst. | BC1: Bank Name of Skilled Asst. | BD1: IFSC Code of Skilled Asst. | BE1: Branch of Skilled Asst. | BF1: Amount in words Skil. Assist | BH1: Title of Lab Technician | BI1: Name of Lab Technician | BJ1: Department of Lab Technician | BK1: College of Lab Technician | BL1: Phone No. of Lab Technician | BM1: No. of Cands. Regd. | BN1: No. of Cands. Examined | BO1: TOTAL | BP1: Account No. of Lab Technician | BQ1: Bank Name of Lab Technician | BR1: IFSC Code of Lab Technician | BS1: Bank Branch of Lab Technician | BT1: Amount in words Lab Tech.
A2: ='Paste here'!A2 -> 0 | B2: ='Paste here'!F2 -> UG | C2: ='Paste here'!J2 -> ECE | D2: ='Paste here'!K2 -> I | E2: =UPPER('Paste here'!H2) -> GEA1107 | F2: ='Paste here'!I2 -> C PROGRAMMING | G2: ='Paste here'!G2 -> TCPL | H2: ='Paste here'!D2 -> 06.06.2026 | I2: ='Paste here'!E2 -> Only FN | K2: ='Paste here'!O2 -> Mrs. | L2: =UPPER('Paste here'!P2) -> RANJANI U | M2: ='Paste here'!S2 -> Assistant Professor | N2: ='Paste here'!R2 -> AIDS | O2: ='Paste here'!T2 -> MAM SCHOOL OF ENGINEERING (8121) | P2: =IF(VLOOKUP(O2,'Distance matrix'!B$2:C$238,2,FALSE)<36,"<35",VLOOKUP(O2,'Distance matrix'!B$2:C$238,2,FALSE)) -> <35 | Q2: ='Paste here'!Q2 -> 8270981412 | R2: ='Paste here'!M2 -> 23 | S2: ='Paste here'!N2 -> 22 | T2: =External!K2 -> 440 | U2: =External!M2 -> 150 | V2: =External!L2 -> 250 | W2: =External!N2 -> 840 | X2: ='Paste here'!U2 -> 6658000400036837 | Y2: =UPPER('Paste here'!V2) -> PUNJAB NATIONAL BANK | Z2: =UPPER('Paste here'!W2) -> PUNB0665800 | AA2: =UPPER('Paste here'!X2) -> SIRUGANUR | AB2: =External!O2 -> Rupees Eight Hundred Fourty Only | AD2: ='Paste here'!Y2 -> Mr. | AE2: =UPPER('Paste here'!Z2) -> KASTHURI RENGAN P | AF2: ='Paste here'!AC2 -> Assistant Professor | AG2: ='Paste here'!AB2 -> CSE | AH2: KRCE | AI2: ='Paste here'!AA2 -> 9842612131 | AJ2: ='Paste here'!M2 -> 23 | AK2: ='Paste here'!N2 -> 22 | AL2: =Internal!L2 -> 440 | AM2: ='Paste here'!AD2 -> 913010015846824 | AN2: =UPPER('Paste here'!AE2) -> AXIS BANK | AO2: =UPPER('Paste here'!AF2) -> UTIB0001746 | AP2: =UPPER('Paste here'!AG2) -> KOTTUR | AQ2: =Internal!M2 -> Rupees Four Hundred Fourty Only | AS2: =IF(OR(G2="TCPL",G2="PRACTICAL - UG",G2="PRACTICAL - PG"),'Paste here'!AH2,"") -> Mrs. | AT2: =UPPER(IF(OR(G2="TCPL",G2="PRACTICAL - UG",G2="PRACTICAL - PG"),'Paste here'!AI2," -NA- ")) -> SURYA G | AU2: =IF(OR(G2="TCPL",G2="PRACTICAL - UG",G2="PRACTICAL - PG"),'Paste here'!AL2," -NA- ") -> Assistant Professor | AV2: =IF(OR(G2="TCPL",G2="PRACTICAL - UG",G2="PRACTICAL - PG"),'Paste here'!AK2," -NA- ") -> CSE | AW2: =IF(OR(G2="TCPL",G2="PRACTICAL - UG",G2="PRACTICAL - PG"),"KRCE"," -NA- ") -> KRCE | AX2: =IF(OR(G2="TCPL",G2="PRACTICAL - UG",G2="PRACTICAL - PG"),'Paste here'!AJ2," -NA- ") -> 8220915957 | AY2: =IF(OR(G2="TCPL",G2="PRACTICAL - UG",G2="PRACTICAL - PG"),'Paste here'!M2," -NA- ") -> 23 | AZ2: =IF(OR(G2="TCPL",G2="PRACTICAL - UG",G2="PRACTICAL - PG"),'Paste here'!N2," -NA- ") -> 22 | BA2: =IF(OR(G2="TCPL",G2="PRACTICAL - UG",G2="PRACTICAL - PG"),Skilled!K2," -NA- ") -> 230 | BB2: =IF(OR(G2="TCPL",G2="PRACTICAL - UG",G2="PRACTICAL - PG"),'Paste here'!AM2," -NA- ") -> 609301501667 | BC2: =UPPER(IF(OR(G2="TCPL",G2="PRACTICAL - UG",G2="PRACTICAL - PG"),'Paste here'!AN2," -NA- ")) -> ICICI BANK | BD2: =UPPER(IF(OR(G2="TCPL",G2="PRACTICAL - UG",G2="PRACTICAL - PG"),'Paste here'!AO2," -NA- ")) -> ICIC0006093 | BE2: =UPPER(IF(OR(G2="TCPL",G2="PRACTICAL - UG",G2="PRACTICAL - PG"),'Paste here'!AP2," -NA- ")) -> JAWAHAR STREET NACHANDUPATTI | BF2: =IF(OR(G2="TCPL",G2="PRACTICAL - UG",G2="PRACTICAL - PG"),Skilled!L2,"") -> Rupees Two Hundred Thirty Only | BH2: =IF(OR(AG2="ENGLISH",AG2="MBA"),"",IF(OR(G2="PRACTICAL - UG",G2="PRACTICAL - PG"),'Paste here'!AQ2,"")) | BI2: =UPPER(IF(OR(G2="PRACTICAL - UG",G2="PRACTICAL - PG"),'Paste here'!AR2," -NA- ")) -> -NA- | BJ2: =IF(OR(G2="PRACTICAL - UG",G2="PRACTICAL - PG"),'Paste here'!AT2," -NA- ") -> -NA- | BK2: =IF(OR(AG2="ENGLISH",AG2="MBA"),"-NA-",IF(OR(G2="PRACTICAL - UG",G2="PRACTICAL - PG"),"KRCE"," -NA- ")) -> -NA- | BL2: =IF(OR(G2="PRACTICAL - UG",G2="PRACTICAL - PG"),'Paste here'!AS2," -NA- ") -> -NA- | BM2: =IF(OR(G2="PRACTICAL - UG",G2="PRACTICAL - PG"),'Paste here'!M2," -NA- ") -> -NA- | BN2: =IF(OR(G2="PRACTICAL - UG",G2="PRACTICAL - PG"),'Paste here'!N2," -NA- ") -> -NA- | BO2: =IF(OR(AG2="ENGLISH",AG2="MBA"),"",IF(OR(G2="PRACTICAL - UG",G2="PRACTICAL - PG"),Technician!J2," -NA- ")) -> -NA- | BP2: =IF(OR(G2="PRACTICAL - UG",G2="PRACTICAL - PG"),'Paste here'!AU2," -NA- ") -> -NA- | BQ2: =UPPER(IF(OR(,G2="PRACTICAL - UG",G2="PRACTICAL - PG"),'Paste here'!AV2," -NA- ")) -> -NA- | BR2: =UPPER(IF(OR(G2="PRACTICAL - UG",G2="PRACTICAL - PG"),'Paste here'!AW2," -NA- ")) -> -NA- | BS2: =UPPER(IF(OR(G2="PRACTICAL - UG",G2="PRACTICAL - PG"),'Paste here'!AX2," -NA- ")) -> -NA- | BT2: =IF(OR(AG2="ENGLISH",AG2="MBA"),"",IF(OR(G2="PRACTICAL - UG",G2="PRACTICAL - PG"),Technician!L2,""))
A3: ='Paste here'!A3 -> 0 | B3: ='Paste here'!F3 -> 0 | C3: ='Paste here'!J3 -> 0 | D3: ='Paste here'!K3 -> 0 | E3: =UPPER('Paste here'!H3) | F3: ='Paste here'!I3 -> 0 | G3: ='Paste here'!G3 -> 0 | H3: ='Paste here'!D3 -> 0 | I3: ='Paste here'!E3 -> 0 | K3: ='Paste here'!O3 -> 0 | L3: =UPPER('Paste here'!P3) | M3: ='Paste here'!S3 -> 0 | N3: ='Paste here'!R3 -> 0 | O3: ='Paste here'!T3 -> 0 | P3: =IF(VLOOKUP(O3,'Distance matrix'!B$2:C$238,2,FALSE)<36,"<35",VLOOKUP(O3,'Distance matrix'!B$2:C$238,2,FALSE)) -> #N/A | Q3: ='Paste here'!Q3 -> 0 | R3: ='Paste here'!M3 -> 0 | S3: ='Paste here'!N3 -> 0 | T3: =External!K3 -> #N/A | U3: =External!M3 -> 0 | V3: =External!L3 -> 0 | W3: =External!N3 -> #N/A | X3: ='Paste here'!U3 -> 0 | Y3: =UPPER('Paste here'!V3) | Z3: =UPPER('Paste here'!W3) | AA3: =UPPER('Paste here'!X3) | AB3: =External!O3 -> #VALUE! | AD3: ='Paste here'!Y3 -> 0 | AE3: =UPPER('Paste here'!Z3) | AF3: ='Paste here'!AC3 -> 0 | AG3: ='Paste here'!AB3 -> 0 | AH3: KRCE | AI3: ='Paste here'!AA3 -> 0 | AJ3: ='Paste here'!M3 -> 0 | AK3: ='Paste here'!N3 -> 0 | AL3: =Internal!L3 -> #N/A | AM3: ='Paste here'!AD3 -> 0 | AN3: =UPPER('Paste here'!AE3) | AO3: =UPPER('Paste here'!AF3) | AP3: =UPPER('Paste here'!AG3) | AQ3: =Internal!M3 -> #VALUE! | AS3: =IF(OR(G3="TCPL",G3="PRACTICAL - UG",G3="PRACTICAL - PG"),'Paste here'!AH3,"") | AT3: =UPPER(IF(OR(G3="TCPL",G3="PRACTICAL - UG",G3="PRACTICAL - PG"),'Paste here'!AI3," -NA- ")) -> -NA- | AU3: =IF(OR(G3="TCPL",G3="PRACTICAL - UG",G3="PRACTICAL - PG"),'Paste here'!AL3," -NA- ") -> -NA- | AV3: =IF(OR(G3="TCPL",G3="PRACTICAL - UG",G3="PRACTICAL - PG"),'Paste here'!AK3," -NA- ") -> -NA- | AW3: =IF(OR(G3="TCPL",G3="PRACTICAL - UG",G3="PRACTICAL - PG"),"KRCE"," -NA- ") -> -NA- | AX3: =IF(OR(G3="TCPL",G3="PRACTICAL - UG",G3="PRACTICAL - PG"),'Paste here'!AJ3," -NA- ") -> -NA- | AY3: =IF(OR(G3="TCPL",G3="PRACTICAL - UG",G3="PRACTICAL - PG"),'Paste here'!M3," -NA- ") -> -NA- | AZ3: =IF(OR(G3="TCPL",G3="PRACTICAL - UG",G3="PRACTICAL - PG"),'Paste here'!N3," -NA- ") -> -NA- | BA3: =IF(OR(G3="TCPL",G3="PRACTICAL - UG",G3="PRACTICAL - PG"),Skilled!K3," -NA- ") -> -NA- | BB3: =IF(OR(G3="TCPL",G3="PRACTICAL - UG",G3="PRACTICAL - PG"),'Paste here'!AM3," -NA- ") -> -NA- | BC3: =UPPER(IF(OR(G3="TCPL",G3="PRACTICAL - UG",G3="PRACTICAL - PG"),'Paste here'!AN3," -NA- ")) -> -NA- | BD3: =UPPER(IF(OR(G3="TCPL",G3="PRACTICAL - UG",G3="PRACTICAL - PG"),'Paste here'!AO3," -NA- ")) -> -NA- | BE3: =UPPER(IF(OR(G3="TCPL",G3="PRACTICAL - UG",G3="PRACTICAL - PG"),'Paste here'!AP3," -NA- ")) -> -NA- | BF3: =IF(OR(G3="TCPL",G3="PRACTICAL - UG",G3="PRACTICAL - PG"),Skilled!L3,"") | BH3: =IF(OR(AG3="ENGLISH",AG3="MBA"),"",IF(OR(G3="PRACTICAL - UG",G3="PRACTICAL - PG"),'Paste here'!AQ3,"")) | BI3: =UPPER(IF(OR(G3="PRACTICAL - UG",G3="PRACTICAL - PG"),'Paste here'!AR3," -NA- ")) -> -NA- | BJ3: =IF(OR(G3="PRACTICAL - UG",G3="PRACTICAL - PG"),'Paste here'!AT3," -NA- ") -> -NA- | BK3: =IF(OR(AG3="ENGLISH",AG3="MBA"),"-NA-",IF(OR(G3="PRACTICAL - UG",G3="PRACTICAL - PG"),"KRCE"," -NA- ")) -> -NA- | BL3: =IF(OR(G3="PRACTICAL - UG",G3="PRACTICAL - PG"),'Paste here'!AS3," -NA- ") -> -NA- | BM3: =IF(OR(G3="PRACTICAL - UG",G3="PRACTICAL - PG"),'Paste here'!M3," -NA- ") -> -NA- | BN3: =IF(OR(G3="PRACTICAL - UG",G3="PRACTICAL - PG"),'Paste here'!N3," -NA- ") -> -NA- | BO3: =IF(OR(AG3="ENGLISH",AG3="MBA"),"",IF(OR(G3="PRACTICAL - UG",G3="PRACTICAL - PG"),Technician!J3," -NA- ")) -> -NA- | BP3: =IF(OR(G3="PRACTICAL - UG",G3="PRACTICAL - PG"),'Paste here'!AU3," -NA- ") -> -NA- | BQ3: =UPPER(IF(OR(,G3="PRACTICAL - UG",G3="PRACTICAL - PG"),'Paste here'!AV3," -NA- ")) -> -NA- | BR3: =UPPER(IF(OR(G3="PRACTICAL - UG",G3="PRACTICAL - PG"),'Paste here'!AW3," -NA- ")) -> -NA- | BS3: =UPPER(IF(OR(G3="PRACTICAL - UG",G3="PRACTICAL - PG"),'Paste here'!AX3," -NA- ")) -> -NA- | BT3: =IF(OR(AG3="ENGLISH",AG3="MBA"),"",IF(OR(G3="PRACTICAL - UG",G3="PRACTICAL - PG"),Technician!L3,""))
A4: ='Paste here'!A4 -> 0 | B4: ='Paste here'!F4 -> 0 | C4: ='Paste here'!J4 -> 0 | D4: ='Paste here'!K4 -> 0 | E4: =UPPER('Paste here'!H4) | F4: ='Paste here'!I4 -> 0 | G4: ='Paste here'!G4 -> 0 | H4: ='Paste here'!D4 -> 0 | I4: ='Paste here'!E4 -> 0 | K4: ='Paste here'!O4 -> 0 | L4: =UPPER('Paste here'!P4) | M4: ='Paste here'!S4 -> 0 | N4: ='Paste here'!R4 -> 0 | O4: ='Paste here'!T4 -> 0 | P4: =IF(VLOOKUP(O4,'Distance matrix'!B$2:C$238,2,FALSE)<36,"<35",VLOOKUP(O4,'Distance matrix'!B$2:C$238,2,FALSE)) -> #N/A | Q4: ='Paste here'!Q4 -> 0 | R4: ='Paste here'!M4 -> 0 | S4: ='Paste here'!N4 -> 0 | T4: =External!K4 -> #N/A | U4: =External!M4 -> 0 | V4: =External!L4 -> 0 | W4: =External!N4 -> #N/A | X4: ='Paste here'!U4 -> 0 | Y4: =UPPER('Paste here'!V4) | Z4: =UPPER('Paste here'!W4) | AA4: =UPPER('Paste here'!X4) | AB4: =External!O4 -> #VALUE! | AD4: ='Paste here'!Y4 -> 0 | AE4: =UPPER('Paste here'!Z4) | AF4: ='Paste here'!AC4 -> 0 | AG4: ='Paste here'!AB4 -> 0 | AH4: KRCE | AI4: ='Paste here'!AA4 -> 0 | AJ4: ='Paste here'!M4 -> 0 | AK4: ='Paste here'!N4 -> 0 | AL4: =Internal!L4 -> #N/A | AM4: ='Paste here'!AD4 -> 0 | AN4: =UPPER('Paste here'!AE4) | AO4: =UPPER('Paste here'!AF4) | AP4: =UPPER('Paste here'!AG4) | AQ4: =Internal!M4 -> #VALUE! | AS4: =IF(OR(G4="TCPL",G4="PRACTICAL - UG",G4="PRACTICAL - PG"),'Paste here'!AH4,"") | AT4: =UPPER(IF(OR(G4="TCPL",G4="PRACTICAL - UG",G4="PRACTICAL - PG"),'Paste here'!AI4," -NA- ")) -> -NA- | AU4: =IF(OR(G4="TCPL",G4="PRACTICAL - UG",G4="PRACTICAL - PG"),'Paste here'!AL4," -NA- ") -> -NA- | AV4: =IF(OR(G4="TCPL",G4="PRACTICAL - UG",G4="PRACTICAL - PG"),'Paste here'!AK4," -NA- ") -> -NA- | AW4: =IF(OR(G4="TCPL",G4="PRACTICAL - UG",G4="PRACTICAL - PG"),"KRCE"," -NA- ") -> -NA- | AX4: =IF(OR(G4="TCPL",G4="PRACTICAL - UG",G4="PRACTICAL - PG"),'Paste here'!AJ4," -NA- ") -> -NA- | AY4: =IF(OR(G4="TCPL",G4="PRACTICAL - UG",G4="PRACTICAL - PG"),'Paste here'!M4," -NA- ") -> -NA- | AZ4: =IF(OR(G4="TCPL",G4="PRACTICAL - UG",G4="PRACTICAL - PG"),'Paste here'!N4," -NA- ") -> -NA- | BA4: =IF(OR(G4="TCPL",G4="PRACTICAL - UG",G4="PRACTICAL - PG"),Skilled!K4," -NA- ") -> -NA- | BB4: =IF(OR(G4="TCPL",G4="PRACTICAL - UG",G4="PRACTICAL - PG"),'Paste here'!AM4," -NA- ") -> -NA- | BC4: =UPPER(IF(OR(G4="TCPL",G4="PRACTICAL - UG",G4="PRACTICAL - PG"),'Paste here'!AN4," -NA- ")) -> -NA- | BD4: =UPPER(IF(OR(G4="TCPL",G4="PRACTICAL - UG",G4="PRACTICAL - PG"),'Paste here'!AO4," -NA- ")) -> -NA- | BE4: =UPPER(IF(OR(G4="TCPL",G4="PRACTICAL - UG",G4="PRACTICAL - PG"),'Paste here'!AP4," -NA- ")) -> -NA- | BF4: =IF(OR(G4="TCPL",G4="PRACTICAL - UG",G4="PRACTICAL - PG"),Skilled!L4,"") | BH4: =IF(OR(AG4="ENGLISH",AG4="MBA"),"",IF(OR(G4="PRACTICAL - UG",G4="PRACTICAL - PG"),'Paste here'!AQ4,"")) | BI4: =UPPER(IF(OR(G4="PRACTICAL - UG",G4="PRACTICAL - PG"),'Paste here'!AR4," -NA- ")) -> -NA- | BJ4: =IF(OR(G4="PRACTICAL - UG",G4="PRACTICAL - PG"),'Paste here'!AT4," -NA- ") -> -NA- | BK4: =IF(OR(AG4="ENGLISH",AG4="MBA"),"-NA-",IF(OR(G4="PRACTICAL - UG",G4="PRACTICAL - PG"),"KRCE"," -NA- ")) -> -NA- | BL4: =IF(OR(G4="PRACTICAL - UG",G4="PRACTICAL - PG"),'Paste here'!AS4," -NA- ") -> -NA- | BM4: =IF(OR(G4="PRACTICAL - UG",G4="PRACTICAL - PG"),'Paste here'!M4," -NA- ") -> -NA- | BN4: =IF(OR(G4="PRACTICAL - UG",G4="PRACTICAL - PG"),'Paste here'!N4," -NA- ") -> -NA- | BO4: =IF(OR(AG4="ENGLISH",AG4="MBA"),"",IF(OR(G4="PRACTICAL - UG",G4="PRACTICAL - PG"),Technician!J4," -NA- ")) -> -NA- | BP4: =IF(OR(G4="PRACTICAL - UG",G4="PRACTICAL - PG"),'Paste here'!AU4," -NA- ") -> -NA- | BQ4: =UPPER(IF(OR(,G4="PRACTICAL - UG",G4="PRACTICAL - PG"),'Paste here'!AV4," -NA- ")) -> -NA- | BR4: =UPPER(IF(OR(G4="PRACTICAL - UG",G4="PRACTICAL - PG"),'Paste here'!AW4," -NA- ")) -> -NA- | BS4: =UPPER(IF(OR(G4="PRACTICAL - UG",G4="PRACTICAL - PG"),'Paste here'!AX4," -NA- ")) -> -NA- | BT4: =IF(OR(AG4="ENGLISH",AG4="MBA"),"",IF(OR(G4="PRACTICAL - UG",G4="PRACTICAL - PG"),Technician!L4,""))
A5: ='Paste here'!A5 -> 0 | B5: ='Paste here'!F5 -> 0 | C5: ='Paste here'!J5 -> 0 | D5: ='Paste here'!K5 -> 0 | E5: =UPPER('Paste here'!H5) | F5: ='Paste here'!I5 -> 0 | G5: ='Paste here'!G5 -> 0 | H5: ='Paste here'!D5 -> 0 | I5: ='Paste here'!E5 -> 0 | K5: ='Paste here'!O5 -> 0 | L5: =UPPER('Paste here'!P5) | M5: ='Paste here'!S5 -> 0 | N5: ='Paste here'!R5 -> 0 | O5: ='Paste here'!T5 -> 0 | P5: =IF(VLOOKUP(O5,'Distance matrix'!B$2:C$238,2,FALSE)<36,"<35",VLOOKUP(O5,'Distance matrix'!B$2:C$238,2,FALSE)) -> #N/A | Q5: ='Paste here'!Q5 -> 0 | R5: ='Paste here'!M5 -> 0 | S5: ='Paste here'!N5 -> 0 | T5: =External!K5 -> #N/A | U5: =External!M5 -> 0 | V5: =External!L5 -> 0 | W5: =External!N5 -> #N/A | X5: ='Paste here'!U5 -> 0 | Y5: =UPPER('Paste here'!V5) | Z5: =UPPER('Paste here'!W5) | AA5: =UPPER('Paste here'!X5) | AB5: =External!O5 -> #VALUE! | AD5: ='Paste here'!Y5 -> 0 | AE5: =UPPER('Paste here'!Z5) | AF5: ='Paste here'!AC5 -> 0 | AG5: ='Paste here'!AB5 -> 0 | AH5: KRCE | AI5: ='Paste here'!AA5 -> 0 | AJ5: ='Paste here'!M5 -> 0 | AK5: ='Paste here'!N5 -> 0 | AL5: =Internal!L5 -> #N/A | AM5: ='Paste here'!AD5 -> 0 | AN5: =UPPER('Paste here'!AE5) | AO5: =UPPER('Paste here'!AF5) | AP5: =UPPER('Paste here'!AG5) | AQ5: =Internal!M5 -> #VALUE! | AS5: =IF(OR(G5="TCPL",G5="PRACTICAL - UG",G5="PRACTICAL - PG"),'Paste here'!AH5,"") | AT5: =UPPER(IF(OR(G5="TCPL",G5="PRACTICAL - UG",G5="PRACTICAL - PG"),'Paste here'!AI5," -NA- ")) -> -NA- | AU5: =IF(OR(G5="TCPL",G5="PRACTICAL - UG",G5="PRACTICAL - PG"),'Paste here'!AL5," -NA- ") -> -NA- | AV5: =IF(OR(G5="TCPL",G5="PRACTICAL - UG",G5="PRACTICAL - PG"),'Paste here'!AK5," -NA- ") -> -NA- | AW5: =IF(OR(G5="TCPL",G5="PRACTICAL - UG",G5="PRACTICAL - PG"),"KRCE"," -NA- ") -> -NA- | AX5: =IF(OR(G5="TCPL",G5="PRACTICAL - UG",G5="PRACTICAL - PG"),'Paste here'!AJ5," -NA- ") -> -NA- | AY5: =IF(OR(G5="TCPL",G5="PRACTICAL - UG",G5="PRACTICAL - PG"),'Paste here'!M5," -NA- ") -> -NA- | AZ5: =IF(OR(G5="TCPL",G5="PRACTICAL - UG",G5="PRACTICAL - PG"),'Paste here'!N5," -NA- ") -> -NA- | BA5: =IF(OR(G5="TCPL",G5="PRACTICAL - UG",G5="PRACTICAL - PG"),Skilled!K5," -NA- ") -> -NA- | BB5: =IF(OR(G5="TCPL",G5="PRACTICAL - UG",G5="PRACTICAL - PG"),'Paste here'!AM5," -NA- ") -> -NA- | BC5: =UPPER(IF(OR(G5="TCPL",G5="PRACTICAL - UG",G5="PRACTICAL - PG"),'Paste here'!AN5," -NA- ")) -> -NA- | BD5: =UPPER(IF(OR(G5="TCPL",G5="PRACTICAL - UG",G5="PRACTICAL - PG"),'Paste here'!AO5," -NA- ")) -> -NA- | BE5: =UPPER(IF(OR(G5="TCPL",G5="PRACTICAL - UG",G5="PRACTICAL - PG"),'Paste here'!AP5," -NA- ")) -> -NA- | BF5: =IF(OR(G5="TCPL",G5="PRACTICAL - UG",G5="PRACTICAL - PG"),Skilled!L5,"") | BH5: =IF(OR(AG5="ENGLISH",AG5="MBA"),"",IF(OR(G5="PRACTICAL - UG",G5="PRACTICAL - PG"),'Paste here'!AQ5,"")) | BI5: =UPPER(IF(OR(G5="PRACTICAL - UG",G5="PRACTICAL - PG"),'Paste here'!AR5," -NA- ")) -> -NA- | BJ5: =IF(OR(G5="PRACTICAL - UG",G5="PRACTICAL - PG"),'Paste here'!AT5," -NA- ") -> -NA- | BK5: =IF(OR(AG5="ENGLISH",AG5="MBA"),"-NA-",IF(OR(G5="PRACTICAL - UG",G5="PRACTICAL - PG"),"KRCE"," -NA- ")) -> -NA- | BL5: =IF(OR(G5="PRACTICAL - UG",G5="PRACTICAL - PG"),'Paste here'!AS5," -NA- ") -> -NA- | BM5: =IF(OR(G5="PRACTICAL - UG",G5="PRACTICAL - PG"),'Paste here'!M5," -NA- ") -> -NA- | BN5: =IF(OR(G5="PRACTICAL - UG",G5="PRACTICAL - PG"),'Paste here'!N5," -NA- ") -> -NA- | BO5: =IF(OR(AG5="ENGLISH",AG5="MBA"),"",IF(OR(G5="PRACTICAL - UG",G5="PRACTICAL - PG"),Technician!J5," -NA- ")) -> -NA- | BP5: =IF(OR(G5="PRACTICAL - UG",G5="PRACTICAL - PG"),'Paste here'!AU5," -NA- ") -> -NA- | BQ5: =UPPER(IF(OR(,G5="PRACTICAL - UG",G5="PRACTICAL - PG"),'Paste here'!AV5," -NA- ")) -> -NA- | BR5: =UPPER(IF(OR(G5="PRACTICAL - UG",G5="PRACTICAL - PG"),'Paste here'!AW5," -NA- ")) -> -NA- | BS5: =UPPER(IF(OR(G5="PRACTICAL - UG",G5="PRACTICAL - PG"),'Paste here'!AX5," -NA- ")) -> -NA- | BT5: =IF(OR(AG5="ENGLISH",AG5="MBA"),"",IF(OR(G5="PRACTICAL - UG",G5="PRACTICAL - PG"),Technician!L5,""))
A6: ='Paste here'!A6 -> 0 | B6: ='Paste here'!F6 -> 0 | C6: ='Paste here'!J6 -> 0 | D6: ='Paste here'!K6 -> 0 | E6: =UPPER('Paste here'!H6) | F6: ='Paste here'!I6 -> 0 | G6: ='Paste here'!G6 -> 0 | H6: ='Paste here'!D6 -> 0 | I6: ='Paste here'!E6 -> 0 | K6: ='Paste here'!O6 -> 0 | L6: =UPPER('Paste here'!P6) | M6: ='Paste here'!S6 -> 0 | N6: ='Paste here'!R6 -> 0 | O6: ='Paste here'!T6 -> 0 | P6: =IF(VLOOKUP(O6,'Distance matrix'!B$2:C$238,2,FALSE)<36,"<35",VLOOKUP(O6,'Distance matrix'!B$2:C$238,2,FALSE)) -> #N/A | Q6: ='Paste here'!Q6 -> 0 | R6: ='Paste here'!M6 -> 0 | S6: ='Paste here'!N6 -> 0 | T6: =External!K6 -> #N/A | U6: =External!M6 -> 0 | V6: =External!L6 -> 0 | W6: =External!N6 -> #N/A | X6: ='Paste here'!U6 -> 0 | Y6: =UPPER('Paste here'!V6) | Z6: =UPPER('Paste here'!W6) | AA6: =UPPER('Paste here'!X6) | AB6: =External!O6 -> #VALUE! | AD6: ='Paste here'!Y6 -> 0 | AE6: =UPPER('Paste here'!Z6) | AF6: ='Paste here'!AC6 -> 0 | AG6: ='Paste here'!AB6 -> 0 | AH6: KRCE | AI6: ='Paste here'!AA6 -> 0 | AJ6: ='Paste here'!M6 -> 0 | AK6: ='Paste here'!N6 -> 0 | AL6: =Internal!L6 -> #N/A | AM6: ='Paste here'!AD6 -> 0 | AN6: =UPPER('Paste here'!AE6) | AO6: =UPPER('Paste here'!AF6) | AP6: =UPPER('Paste here'!AG6) | AQ6: =Internal!M6 -> #VALUE! | AS6: =IF(OR(G6="TCPL",G6="PRACTICAL - UG",G6="PRACTICAL - PG"),'Paste here'!AH6,"") | AT6: =UPPER(IF(OR(G6="TCPL",G6="PRACTICAL - UG",G6="PRACTICAL - PG"),'Paste here'!AI6," -NA- ")) -> -NA- | AU6: =IF(OR(G6="TCPL",G6="PRACTICAL - UG",G6="PRACTICAL - PG"),'Paste here'!AL6," -NA- ") -> -NA- | AV6: =IF(OR(G6="TCPL",G6="PRACTICAL - UG",G6="PRACTICAL - PG"),'Paste here'!AK6," -NA- ") -> -NA- | AW6: =IF(OR(G6="TCPL",G6="PRACTICAL - UG",G6="PRACTICAL - PG"),"KRCE"," -NA- ") -> -NA- | AX6: =IF(OR(G6="TCPL",G6="PRACTICAL - UG",G6="PRACTICAL - PG"),'Paste here'!AJ6," -NA- ") -> -NA- | AY6: =IF(OR(G6="TCPL",G6="PRACTICAL - UG",G6="PRACTICAL - PG"),'Paste here'!M6," -NA- ") -> -NA- | AZ6: =IF(OR(G6="TCPL",G6="PRACTICAL - UG",G6="PRACTICAL - PG"),'Paste here'!N6," -NA- ") -> -NA- | BA6: =IF(OR(G6="TCPL",G6="PRACTICAL - UG",G6="PRACTICAL - PG"),Skilled!K6," -NA- ") -> -NA- | BB6: =IF(OR(G6="TCPL",G6="PRACTICAL - UG",G6="PRACTICAL - PG"),'Paste here'!AM6," -NA- ") -> -NA- | BC6: =UPPER(IF(OR(G6="TCPL",G6="PRACTICAL - UG",G6="PRACTICAL - PG"),'Paste here'!AN6," -NA- ")) -> -NA- | BD6: =UPPER(IF(OR(G6="TCPL",G6="PRACTICAL - UG",G6="PRACTICAL - PG"),'Paste here'!AO6," -NA- ")) -> -NA- | BE6: =UPPER(IF(OR(G6="TCPL",G6="PRACTICAL - UG",G6="PRACTICAL - PG"),'Paste here'!AP6," -NA- ")) -> -NA- | BF6: =IF(OR(G6="TCPL",G6="PRACTICAL - UG",G6="PRACTICAL - PG"),Skilled!L6,"") | BH6: =IF(OR(AG6="ENGLISH",AG6="MBA"),"",IF(OR(G6="PRACTICAL - UG",G6="PRACTICAL - PG"),'Paste here'!AQ6,"")) | BI6: =UPPER(IF(OR(G6="PRACTICAL - UG",G6="PRACTICAL - PG"),'Paste here'!AR6," -NA- ")) -> -NA- | BJ6: =IF(OR(G6="PRACTICAL - UG",G6="PRACTICAL - PG"),'Paste here'!AT6," -NA- ") -> -NA- | BK6: =IF(OR(AG6="ENGLISH",AG6="MBA"),"-NA-",IF(OR(G6="PRACTICAL - UG",G6="PRACTICAL - PG"),"KRCE"," -NA- ")) -> -NA- | BL6: =IF(OR(G6="PRACTICAL - UG",G6="PRACTICAL - PG"),'Paste here'!AS6," -NA- ") -> -NA- | BM6: =IF(OR(G6="PRACTICAL - UG",G6="PRACTICAL - PG"),'Paste here'!M6," -NA- ") -> -NA- | BN6: =IF(OR(G6="PRACTICAL - UG",G6="PRACTICAL - PG"),'Paste here'!N6," -NA- ") -> -NA- | BO6: =IF(OR(AG6="ENGLISH",AG6="MBA"),"",IF(OR(G6="PRACTICAL - UG",G6="PRACTICAL - PG"),Technician!J6," -NA- ")) -> -NA- | BP6: =IF(OR(G6="PRACTICAL - UG",G6="PRACTICAL - PG"),'Paste here'!AU6," -NA- ") -> -NA- | BQ6: =UPPER(IF(OR(,G6="PRACTICAL - UG",G6="PRACTICAL - PG"),'Paste here'!AV6," -NA- ")) -> -NA- | BR6: =UPPER(IF(OR(G6="PRACTICAL - UG",G6="PRACTICAL - PG"),'Paste here'!AW6," -NA- ")) -> -NA- | BS6: =UPPER(IF(OR(G6="PRACTICAL - UG",G6="PRACTICAL - PG"),'Paste here'!AX6," -NA- ")) -> -NA- | BT6: =IF(OR(AG6="ENGLISH",AG6="MBA"),"",IF(OR(G6="PRACTICAL - UG",G6="PRACTICAL - PG"),Technician!L6,""))
A7: ='Paste here'!A7 -> 0 | B7: ='Paste here'!F7 -> 0 | C7: ='Paste here'!J7 -> 0 | D7: ='Paste here'!K7 -> 0 | E7: =UPPER('Paste here'!H7) | F7: ='Paste here'!I7 -> 0 | G7: ='Paste here'!G7 -> 0 | H7: ='Paste here'!D7 -> 0 | I7: ='Paste here'!E7 -> 0 | K7: ='Paste here'!O7 -> 0 | L7: =UPPER('Paste here'!P7) | M7: ='Paste here'!S7 -> 0 | N7: ='Paste here'!R7 -> 0 | O7: ='Paste here'!T7 -> 0 | P7: =IF(VLOOKUP(O7,'Distance matrix'!B$2:C$238,2,FALSE)<36,"<35",VLOOKUP(O7,'Distance matrix'!B$2:C$238,2,FALSE)) -> #N/A | Q7: ='Paste here'!Q7 -> 0 | R7: ='Paste here'!M7 -> 0 | S7: ='Paste here'!N7 -> 0 | T7: =External!K7 -> #N/A | U7: =External!M7 -> 0 | V7: =External!L7 -> 0 | W7: =External!N7 -> #N/A | X7: ='Paste here'!U7 -> 0 | Y7: =UPPER('Paste here'!V7) | Z7: =UPPER('Paste here'!W7) | AA7: =UPPER('Paste here'!X7) | AB7: =External!O7 -> #VALUE! | AD7: ='Paste here'!Y7 -> 0 | AE7: =UPPER('Paste here'!Z7) | AF7: ='Paste here'!AC7 -> 0 | AG7: ='Paste here'!AB7 -> 0 | AH7: KRCE | AI7: ='Paste here'!AA7 -> 0 | AJ7: ='Paste here'!M7 -> 0 | AK7: ='Paste here'!N7 -> 0 | AL7: =Internal!L7 -> #N/A | AM7: ='Paste here'!AD7 -> 0 | AN7: =UPPER('Paste here'!AE7) | AO7: =UPPER('Paste here'!AF7) | AP7: =UPPER('Paste here'!AG7) | AQ7: =Internal!M7 -> #VALUE! | AS7: =IF(OR(G7="TCPL",G7="PRACTICAL - UG",G7="PRACTICAL - PG"),'Paste here'!AH7,"") | AT7: =UPPER(IF(OR(G7="TCPL",G7="PRACTICAL - UG",G7="PRACTICAL - PG"),'Paste here'!AI7," -NA- ")) -> -NA- | AU7: =IF(OR(G7="TCPL",G7="PRACTICAL - UG",G7="PRACTICAL - PG"),'Paste here'!AL7," -NA- ") -> -NA- | AV7: =IF(OR(G7="TCPL",G7="PRACTICAL - UG",G7="PRACTICAL - PG"),'Paste here'!AK7," -NA- ") -> -NA- | AW7: =IF(OR(G7="TCPL",G7="PRACTICAL - UG",G7="PRACTICAL - PG"),"KRCE"," -NA- ") -> -NA- | AX7: =IF(OR(G7="TCPL",G7="PRACTICAL - UG",G7="PRACTICAL - PG"),'Paste here'!AJ7," -NA- ") -> -NA- | AY7: =IF(OR(G7="TCPL",G7="PRACTICAL - UG",G7="PRACTICAL - PG"),'Paste here'!M7," -NA- ") -> -NA- | AZ7: =IF(OR(G7="TCPL",G7="PRACTICAL - UG",G7="PRACTICAL - PG"),'Paste here'!N7," -NA- ") -> -NA- | BA7: =IF(OR(G7="TCPL",G7="PRACTICAL - UG",G7="PRACTICAL - PG"),Skilled!K7," -NA- ") -> -NA- | BB7: =IF(OR(G7="TCPL",G7="PRACTICAL - UG",G7="PRACTICAL - PG"),'Paste here'!AM7," -NA- ") -> -NA- | BC7: =UPPER(IF(OR(G7="TCPL",G7="PRACTICAL - UG",G7="PRACTICAL - PG"),'Paste here'!AN7," -NA- ")) -> -NA- | BD7: =UPPER(IF(OR(G7="TCPL",G7="PRACTICAL - UG",G7="PRACTICAL - PG"),'Paste here'!AO7," -NA- ")) -> -NA- | BE7: =UPPER(IF(OR(G7="TCPL",G7="PRACTICAL - UG",G7="PRACTICAL - PG"),'Paste here'!AP7," -NA- ")) -> -NA- | BF7: =IF(OR(G7="TCPL",G7="PRACTICAL - UG",G7="PRACTICAL - PG"),Skilled!L7,"") | BH7: =IF(OR(AG7="ENGLISH",AG7="MBA"),"",IF(OR(G7="PRACTICAL - UG",G7="PRACTICAL - PG"),'Paste here'!AQ7,"")) | BI7: =UPPER(IF(OR(G7="PRACTICAL - UG",G7="PRACTICAL - PG"),'Paste here'!AR7," -NA- ")) -> -NA- | BJ7: =IF(OR(G7="PRACTICAL - UG",G7="PRACTICAL - PG"),'Paste here'!AT7," -NA- ") -> -NA- | BK7: =IF(OR(AG7="ENGLISH",AG7="MBA"),"-NA-",IF(OR(G7="PRACTICAL - UG",G7="PRACTICAL - PG"),"KRCE"," -NA- ")) -> -NA- | BL7: =IF(OR(G7="PRACTICAL - UG",G7="PRACTICAL - PG"),'Paste here'!AS7," -NA- ") -> -NA- | BM7: =IF(OR(G7="PRACTICAL - UG",G7="PRACTICAL - PG"),'Paste here'!M7," -NA- ") -> -NA- | BN7: =IF(OR(G7="PRACTICAL - UG",G7="PRACTICAL - PG"),'Paste here'!N7," -NA- ") -> -NA- | BO7: =IF(OR(AG7="ENGLISH",AG7="MBA"),"",IF(OR(G7="PRACTICAL - UG",G7="PRACTICAL - PG"),Technician!J7," -NA- ")) -> -NA- | BP7: =IF(OR(G7="PRACTICAL - UG",G7="PRACTICAL - PG"),'Paste here'!AU7," -NA- ") -> -NA- | BQ7: =UPPER(IF(OR(,G7="PRACTICAL - UG",G7="PRACTICAL - PG"),'Paste here'!AV7," -NA- ")) -> -NA- | BR7: =UPPER(IF(OR(G7="PRACTICAL - UG",G7="PRACTICAL - PG"),'Paste here'!AW7," -NA- ")) -> -NA- | BS7: =UPPER(IF(OR(G7="PRACTICAL - UG",G7="PRACTICAL - PG"),'Paste here'!AX7," -NA- ")) -> -NA- | BT7: =IF(OR(AG7="ENGLISH",AG7="MBA"),"",IF(OR(G7="PRACTICAL - UG",G7="PRACTICAL - PG"),Technician!L7,""))
A8: ='Paste here'!A8 -> 0 | B8: ='Paste here'!F8 -> 0 | C8: ='Paste here'!J8 -> 0 | D8: ='Paste here'!K8 -> 0 | E8: =UPPER('Paste here'!H8) | F8: ='Paste here'!I8 -> 0 | G8: ='Paste here'!G8 -> 0 | H8: ='Paste here'!D8 -> 0 | I8: ='Paste here'!E8 -> 0 | K8: ='Paste here'!O8 -> 0 | L8: =UPPER('Paste here'!P8) | M8: ='Paste here'!S8 -> 0 | N8: ='Paste here'!R8 -> 0 | O8: ='Paste here'!T8 -> 0 | P8: =IF(VLOOKUP(O8,'Distance matrix'!B$2:C$238,2,FALSE)<36,"<35",VLOOKUP(O8,'Distance matrix'!B$2:C$238,2,FALSE)) -> #N/A | Q8: ='Paste here'!Q8 -> 0 | R8: ='Paste here'!M8 -> 0 | S8: ='Paste here'!N8 -> 0 | T8: =External!K8 -> #N/A | U8: =External!M8 -> 0 | V8: =External!L8 -> 0 | W8: =External!N8 -> #N/A | X8: ='Paste here'!U8 -> 0 | Y8: =UPPER('Paste here'!V8) | Z8: =UPPER('Paste here'!W8) | AA8: =UPPER('Paste here'!X8) | AB8: =External!O8 -> #VALUE! | AD8: ='Paste here'!Y8 -> 0 | AE8: =UPPER('Paste here'!Z8) | AF8: ='Paste here'!AC8 -> 0 | AG8: ='Paste here'!AB8 -> 0 | AH8: KRCE | AI8: ='Paste here'!AA8 -> 0 | AJ8: ='Paste here'!M8 -> 0 | AK8: ='Paste here'!N8 -> 0 | AL8: =Internal!L8 -> #N/A | AM8: ='Paste here'!AD8 -> 0 | AN8: =UPPER('Paste here'!AE8) | AO8: =UPPER('Paste here'!AF8) | AP8: =UPPER('Paste here'!AG8) | AQ8: =Internal!M8 -> #VALUE! | AS8: =IF(OR(G8="TCPL",G8="PRACTICAL - UG",G8="PRACTICAL - PG"),'Paste here'!AH8,"") | AT8: =UPPER(IF(OR(G8="TCPL",G8="PRACTICAL - UG",G8="PRACTICAL - PG"),'Paste here'!AI8," -NA- ")) -> -NA- | AU8: =IF(OR(G8="TCPL",G8="PRACTICAL - UG",G8="PRACTICAL - PG"),'Paste here'!AL8," -NA- ") -> -NA- | AV8: =IF(OR(G8="TCPL",G8="PRACTICAL - UG",G8="PRACTICAL - PG"),'Paste here'!AK8," -NA- ") -> -NA- | AW8: =IF(OR(G8="TCPL",G8="PRACTICAL - UG",G8="PRACTICAL - PG"),"KRCE"," -NA- ") -> -NA- | AX8: =IF(OR(G8="TCPL",G8="PRACTICAL - UG",G8="PRACTICAL - PG"),'Paste here'!AJ8," -NA- ") -> -NA- | AY8: =IF(OR(G8="TCPL",G8="PRACTICAL - UG",G8="PRACTICAL - PG"),'Paste here'!M8," -NA- ") -> -NA- | AZ8: =IF(OR(G8="TCPL",G8="PRACTICAL - UG",G8="PRACTICAL - PG"),'Paste here'!N8," -NA- ") -> -NA- | BA8: =IF(OR(G8="TCPL",G8="PRACTICAL - UG",G8="PRACTICAL - PG"),Skilled!K8," -NA- ") -> -NA- | BB8: =IF(OR(G8="TCPL",G8="PRACTICAL - UG",G8="PRACTICAL - PG"),'Paste here'!AM8," -NA- ") -> -NA- | BC8: =UPPER(IF(OR(G8="TCPL",G8="PRACTICAL - UG",G8="PRACTICAL - PG"),'Paste here'!AN8," -NA- ")) -> -NA- | BD8: =UPPER(IF(OR(G8="TCPL",G8="PRACTICAL - UG",G8="PRACTICAL - PG"),'Paste here'!AO8," -NA- ")) -> -NA- | BE8: =UPPER(IF(OR(G8="TCPL",G8="PRACTICAL - UG",G8="PRACTICAL - PG"),'Paste here'!AP8," -NA- ")) -> -NA- | BF8: =IF(OR(G8="TCPL",G8="PRACTICAL - UG",G8="PRACTICAL - PG"),Skilled!L8,"") | BH8: =IF(OR(AG8="ENGLISH",AG8="MBA"),"",IF(OR(G8="PRACTICAL - UG",G8="PRACTICAL - PG"),'Paste here'!AQ8,"")) | BI8: =UPPER(IF(OR(G8="PRACTICAL - UG",G8="PRACTICAL - PG"),'Paste here'!AR8," -NA- ")) -> -NA- | BJ8: =IF(OR(G8="PRACTICAL - UG",G8="PRACTICAL - PG"),'Paste here'!AT8," -NA- ") -> -NA- | BK8: =IF(OR(AG8="ENGLISH",AG8="MBA"),"-NA-",IF(OR(G8="PRACTICAL - UG",G8="PRACTICAL - PG"),"KRCE"," -NA- ")) -> -NA- | BL8: =IF(OR(G8="PRACTICAL - UG",G8="PRACTICAL - PG"),'Paste here'!AS8," -NA- ") -> -NA- | BM8: =IF(OR(G8="PRACTICAL - UG",G8="PRACTICAL - PG"),'Paste here'!M8," -NA- ") -> -NA- | BN8: =IF(OR(G8="PRACTICAL - UG",G8="PRACTICAL - PG"),'Paste here'!N8," -NA- ") -> -NA- | BO8: =IF(OR(AG8="ENGLISH",AG8="MBA"),"",IF(OR(G8="PRACTICAL - UG",G8="PRACTICAL - PG"),Technician!J8," -NA- ")) -> -NA- | BP8: =IF(OR(G8="PRACTICAL - UG",G8="PRACTICAL - PG"),'Paste here'!AU8," -NA- ") -> -NA- | BQ8: =UPPER(IF(OR(,G8="PRACTICAL - UG",G8="PRACTICAL - PG"),'Paste here'!AV8," -NA- ")) -> -NA- | BR8: =UPPER(IF(OR(G8="PRACTICAL - UG",G8="PRACTICAL - PG"),'Paste here'!AW8," -NA- ")) -> -NA- | BS8: =UPPER(IF(OR(G8="PRACTICAL - UG",G8="PRACTICAL - PG"),'Paste here'!AX8," -NA- ")) -> -NA- | BT8: =IF(OR(AG8="ENGLISH",AG8="MBA"),"",IF(OR(G8="PRACTICAL - UG",G8="PRACTICAL - PG"),Technician!L8,""))
A9: ='Paste here'!A9 -> 0 | B9: ='Paste here'!F9 -> 0 | C9: ='Paste here'!J9 -> 0 | D9: ='Paste here'!K9 -> 0 | E9: =UPPER('Paste here'!H9) | F9: ='Paste here'!I9 -> 0 | G9: ='Paste here'!G9 -> 0 | H9: ='Paste here'!D9 -> 0 | I9: ='Paste here'!E9 -> 0 | K9: ='Paste here'!O9 -> 0 | L9: =UPPER('Paste here'!P9) | M9: ='Paste here'!S9 -> 0 | N9: ='Paste here'!R9 -> 0 | O9: ='Paste here'!T9 -> 0 | P9: =IF(VLOOKUP(O9,'Distance matrix'!B$2:C$238,2,FALSE)<36,"<35",VLOOKUP(O9,'Distance matrix'!B$2:C$238,2,FALSE)) -> #N/A | Q9: ='Paste here'!Q9 -> 0 | R9: ='Paste here'!M9 -> 0 | S9: ='Paste here'!N9 -> 0 | T9: =External!K9 -> #N/A | U9: =External!M9 -> 0 | V9: =External!L9 -> 0 | W9: =External!N9 -> #N/A | X9: ='Paste here'!U9 -> 0 | Y9: =UPPER('Paste here'!V9) | Z9: =UPPER('Paste here'!W9) | AA9: =UPPER('Paste here'!X9) | AB9: =External!O9 -> #VALUE! | AD9: ='Paste here'!Y9 -> 0 | AE9: =UPPER('Paste here'!Z9) | AF9: ='Paste here'!AC9 -> 0 | AG9: ='Paste here'!AB9 -> 0 | AH9: KRCE | AI9: ='Paste here'!AA9 -> 0 | AJ9: ='Paste here'!M9 -> 0 | AK9: ='Paste here'!N9 -> 0 | AL9: =Internal!L9 -> #N/A | AM9: ='Paste here'!AD9 -> 0 | AN9: =UPPER('Paste here'!AE9) | AO9: =UPPER('Paste here'!AF9) | AP9: =UPPER('Paste here'!AG9) | AQ9: =Internal!M9 -> #VALUE! | AS9: =IF(OR(G9="TCPL",G9="PRACTICAL - UG",G9="PRACTICAL - PG"),'Paste here'!AH9,"") | AT9: =UPPER(IF(OR(G9="TCPL",G9="PRACTICAL - UG",G9="PRACTICAL - PG"),'Paste here'!AI9," -NA- ")) -> -NA- | AU9: =IF(OR(G9="TCPL",G9="PRACTICAL - UG",G9="PRACTICAL - PG"),'Paste here'!AL9," -NA- ") -> -NA- | AV9: =IF(OR(G9="TCPL",G9="PRACTICAL - UG",G9="PRACTICAL - PG"),'Paste here'!AK9," -NA- ") -> -NA- | AW9: =IF(OR(G9="TCPL",G9="PRACTICAL - UG",G9="PRACTICAL - PG"),"KRCE"," -NA- ") -> -NA- | AX9: =IF(OR(G9="TCPL",G9="PRACTICAL - UG",G9="PRACTICAL - PG"),'Paste here'!AJ9," -NA- ") -> -NA- | AY9: =IF(OR(G9="TCPL",G9="PRACTICAL - UG",G9="PRACTICAL - PG"),'Paste here'!M9," -NA- ") -> -NA- | AZ9: =IF(OR(G9="TCPL",G9="PRACTICAL - UG",G9="PRACTICAL - PG"),'Paste here'!N9," -NA- ") -> -NA- | BA9: =IF(OR(G9="TCPL",G9="PRACTICAL - UG",G9="PRACTICAL - PG"),Skilled!K9," -NA- ") -> -NA- | BB9: =IF(OR(G9="TCPL",G9="PRACTICAL - UG",G9="PRACTICAL - PG"),'Paste here'!AM9," -NA- ") -> -NA- | BC9: =UPPER(IF(OR(G9="TCPL",G9="PRACTICAL - UG",G9="PRACTICAL - PG"),'Paste here'!AN9," -NA- ")) -> -NA- | BD9: =UPPER(IF(OR(G9="TCPL",G9="PRACTICAL - UG",G9="PRACTICAL - PG"),'Paste here'!AO9," -NA- ")) -> -NA- | BE9: =UPPER(IF(OR(G9="TCPL",G9="PRACTICAL - UG",G9="PRACTICAL - PG"),'Paste here'!AP9," -NA- ")) -> -NA- | BF9: =IF(OR(G9="TCPL",G9="PRACTICAL - UG",G9="PRACTICAL - PG"),Skilled!L9,"") | BH9: =IF(OR(AG9="ENGLISH",AG9="MBA"),"",IF(OR(G9="PRACTICAL - UG",G9="PRACTICAL - PG"),'Paste here'!AQ9,"")) | BI9: =UPPER(IF(OR(G9="PRACTICAL - UG",G9="PRACTICAL - PG"),'Paste here'!AR9," -NA- ")) -> -NA- | BJ9: =IF(OR(G9="PRACTICAL - UG",G9="PRACTICAL - PG"),'Paste here'!AT9," -NA- ") -> -NA- | BK9: =IF(OR(AG9="ENGLISH",AG9="MBA"),"-NA-",IF(OR(G9="PRACTICAL - UG",G9="PRACTICAL - PG"),"KRCE"," -NA- ")) -> -NA- | BL9: =IF(OR(G9="PRACTICAL - UG",G9="PRACTICAL - PG"),'Paste here'!AS9," -NA- ") -> -NA- | BM9: =IF(OR(G9="PRACTICAL - UG",G9="PRACTICAL - PG"),'Paste here'!M9," -NA- ") -> -NA- | BN9: =IF(OR(G9="PRACTICAL - UG",G9="PRACTICAL - PG"),'Paste here'!N9," -NA- ") -> -NA- | BO9: =IF(OR(AG9="ENGLISH",AG9="MBA"),"",IF(OR(G9="PRACTICAL - UG",G9="PRACTICAL - PG"),Technician!J9," -NA- ")) -> -NA- | BP9: =IF(OR(G9="PRACTICAL - UG",G9="PRACTICAL - PG"),'Paste here'!AU9," -NA- ") -> -NA- | BQ9: =UPPER(IF(OR(,G9="PRACTICAL - UG",G9="PRACTICAL - PG"),'Paste here'!AV9," -NA- ")) -> -NA- | BR9: =UPPER(IF(OR(G9="PRACTICAL - UG",G9="PRACTICAL - PG"),'Paste here'!AW9," -NA- ")) -> -NA- | BS9: =UPPER(IF(OR(G9="PRACTICAL - UG",G9="PRACTICAL - PG"),'Paste here'!AX9," -NA- ")) -> -NA- | BT9: =IF(OR(AG9="ENGLISH",AG9="MBA"),"",IF(OR(G9="PRACTICAL - UG",G9="PRACTICAL - PG"),Technician!L9,""))
A10: ='Paste here'!A10 -> 0 | B10: ='Paste here'!F10 -> 0 | C10: ='Paste here'!J10 -> 0 | D10: ='Paste here'!K10 -> 0 | E10: =UPPER('Paste here'!H10) | F10: ='Paste here'!I10 -> 0 | G10: ='Paste here'!G10 -> 0 | H10: ='Paste here'!D10 -> 0 | I10: ='Paste here'!E10 -> 0 | K10: ='Paste here'!O10 -> 0 | L10: =UPPER('Paste here'!P10) | M10: ='Paste here'!S10 -> 0 | N10: ='Paste here'!R10 -> 0 | O10: ='Paste here'!T10 -> 0 | P10: =IF(VLOOKUP(O10,'Distance matrix'!B$2:C$238,2,FALSE)<36,"<35",VLOOKUP(O10,'Distance matrix'!B$2:C$238,2,FALSE)) -> #N/A | Q10: ='Paste here'!Q10 -> 0 | R10: ='Paste here'!M10 -> 0 | S10: ='Paste here'!N10 -> 0 | T10: =External!K10 -> #N/A | U10: =External!M10 -> 0 | V10: =External!L10 -> 0 | W10: =External!N10 -> #N/A | X10: ='Paste here'!U10 -> 0 | Y10: =UPPER('Paste here'!V10) | Z10: =UPPER('Paste here'!W10) | AA10: =UPPER('Paste here'!X10) | AB10: =External!O10 -> #VALUE! | AD10: ='Paste here'!Y10 -> 0 | AE10: =UPPER('Paste here'!Z10) | AF10: ='Paste here'!AC10 -> 0 | AG10: ='Paste here'!AB10 -> 0 | AH10: KRCE | AI10: ='Paste here'!AA10 -> 0 | AJ10: ='Paste here'!M10 -> 0 | AK10: ='Paste here'!N10 -> 0 | AL10: =Internal!L10 -> #N/A | AM10: ='Paste here'!AD10 -> 0 | AN10: =UPPER('Paste here'!AE10) | AO10: =UPPER('Paste here'!AF10) | AP10: =UPPER('Paste here'!AG10) | AQ10: =Internal!M10 -> #VALUE! | AS10: =IF(OR(G10="TCPL",G10="PRACTICAL - UG",G10="PRACTICAL - PG"),'Paste here'!AH10,"") | AT10: =UPPER(IF(OR(G10="TCPL",G10="PRACTICAL - UG",G10="PRACTICAL - PG"),'Paste here'!AI10," -NA- ")) -> -NA- | AU10: =IF(OR(G10="TCPL",G10="PRACTICAL - UG",G10="PRACTICAL - PG"),'Paste here'!AL10," -NA- ") -> -NA- | AV10: =IF(OR(G10="TCPL",G10="PRACTICAL - UG",G10="PRACTICAL - PG"),'Paste here'!AK10," -NA- ") -> -NA- | AW10: =IF(OR(G10="TCPL",G10="PRACTICAL - UG",G10="PRACTICAL - PG"),"KRCE"," -NA- ") -> -NA- | AX10: =IF(OR(G10="TCPL",G10="PRACTICAL - UG",G10="PRACTICAL - PG"),'Paste here'!AJ10," -NA- ") -> -NA- | AY10: =IF(OR(G10="TCPL",G10="PRACTICAL - UG",G10="PRACTICAL - PG"),'Paste here'!M10," -NA- ") -> -NA- | AZ10: =IF(OR(G10="TCPL",G10="PRACTICAL - UG",G10="PRACTICAL - PG"),'Paste here'!N10," -NA- ") -> -NA- | BA10: =IF(OR(G10="TCPL",G10="PRACTICAL - UG",G10="PRACTICAL - PG"),Skilled!K10," -NA- ") -> -NA- | BB10: =IF(OR(G10="TCPL",G10="PRACTICAL - UG",G10="PRACTICAL - PG"),'Paste here'!AM10," -NA- ") -> -NA- | BC10: =UPPER(IF(OR(G10="TCPL",G10="PRACTICAL - UG",G10="PRACTICAL - PG"),'Paste here'!AN10," -NA- ")) -> -NA- | BD10: =UPPER(IF(OR(G10="TCPL",G10="PRACTICAL - UG",G10="PRACTICAL - PG"),'Paste here'!AO10," -NA- ")) -> -NA- | BE10: =UPPER(IF(OR(G10="TCPL",G10="PRACTICAL - UG",G10="PRACTICAL - PG"),'Paste here'!AP10," -NA- ")) -> -NA- | BF10: =IF(OR(G10="TCPL",G10="PRACTICAL - UG",G10="PRACTICAL - PG"),Skilled!L10,"") | BH10: =IF(OR(AG10="ENGLISH",AG10="MBA"),"",IF(OR(G10="PRACTICAL - UG",G10="PRACTICAL - PG"),'Paste here'!AQ10,"")) | BI10: =UPPER(IF(OR(G10="PRACTICAL - UG",G10="PRACTICAL - PG"),'Paste here'!AR10," -NA- ")) -> -NA- | BJ10: =IF(OR(G10="PRACTICAL - UG",G10="PRACTICAL - PG"),'Paste here'!AT10," -NA- ") -> -NA- | BK10: =IF(OR(AG10="ENGLISH",AG10="MBA"),"-NA-",IF(OR(G10="PRACTICAL - UG",G10="PRACTICAL - PG"),"KRCE"," -NA- ")) -> -NA- | BL10: =IF(OR(G10="PRACTICAL - UG",G10="PRACTICAL - PG"),'Paste here'!AS10," -NA- ") -> -NA- | BM10: =IF(OR(G10="PRACTICAL - UG",G10="PRACTICAL - PG"),'Paste here'!M10," -NA- ") -> -NA- | BN10: =IF(OR(G10="PRACTICAL - UG",G10="PRACTICAL - PG"),'Paste here'!N10," -NA- ") -> -NA- | BO10: =IF(OR(AG10="ENGLISH",AG10="MBA"),"",IF(OR(G10="PRACTICAL - UG",G10="PRACTICAL - PG"),Technician!J10," -NA- ")) -> -NA- | BP10: =IF(OR(G10="PRACTICAL - UG",G10="PRACTICAL - PG"),'Paste here'!AU10," -NA- ") -> -NA- | BQ10: =UPPER(IF(OR(,G10="PRACTICAL - UG",G10="PRACTICAL - PG"),'Paste here'!AV10," -NA- ")) -> -NA- | BR10: =UPPER(IF(OR(G10="PRACTICAL - UG",G10="PRACTICAL - PG"),'Paste here'!AW10," -NA- ")) -> -NA- | BS10: =UPPER(IF(OR(G10="PRACTICAL - UG",G10="PRACTICAL - PG"),'Paste here'!AX10," -NA- ")) -> -NA- | BT10: =IF(OR(AG10="ENGLISH",AG10="MBA"),"",IF(OR(G10="PRACTICAL - UG",G10="PRACTICAL - PG"),Technician!L10,""))
A11: ='Paste here'!A11 -> 0 | B11: ='Paste here'!F11 -> 0 | C11: ='Paste here'!J11 -> 0 | D11: ='Paste here'!K11 -> 0 | E11: =UPPER('Paste here'!H11) | F11: ='Paste here'!I11 -> 0 | G11: ='Paste here'!G11 -> 0 | H11: ='Paste here'!D11 -> 0 | I11: ='Paste here'!E11 -> 0 | K11: ='Paste here'!O11 -> 0 | L11: =UPPER('Paste here'!P11) | M11: ='Paste here'!S11 -> 0 | N11: ='Paste here'!R11 -> 0 | O11: ='Paste here'!T11 -> 0 | P11: =IF(VLOOKUP(O11,'Distance matrix'!B$2:C$238,2,FALSE)<36,"<35",VLOOKUP(O11,'Distance matrix'!B$2:C$238,2,FALSE)) -> #N/A | Q11: ='Paste here'!Q11 -> 0 | R11: ='Paste here'!M11 -> 0 | S11: ='Paste here'!N11 -> 0 | T11: =External!K11 -> #N/A | U11: =External!M11 -> 0 | V11: =External!L11 -> 0 | W11: =External!N11 -> #N/A | X11: ='Paste here'!U11 -> 0 | Y11: =UPPER('Paste here'!V11) | Z11: =UPPER('Paste here'!W11) | AA11: =UPPER('Paste here'!X11) | AB11: =External!O11 -> #VALUE! | AD11: ='Paste here'!Y11 -> 0 | AE11: =UPPER('Paste here'!Z11) | AF11: ='Paste here'!AC11 -> 0 | AG11: ='Paste here'!AB11 -> 0 | AH11: KRCE | AI11: ='Paste here'!AA11 -> 0 | AJ11: ='Paste here'!M11 -> 0 | AK11: ='Paste here'!N11 -> 0 | AL11: =Internal!L11 -> #N/A | AM11: ='Paste here'!AD11 -> 0 | AN11: =UPPER('Paste here'!AE11) | AO11: =UPPER('Paste here'!AF11) | AP11: =UPPER('Paste here'!AG11) | AQ11: =Internal!M11 -> #VALUE! | AS11: =IF(OR(G11="TCPL",G11="PRACTICAL - UG",G11="PRACTICAL - PG"),'Paste here'!AH11,"") | AT11: =UPPER(IF(OR(G11="TCPL",G11="PRACTICAL - UG",G11="PRACTICAL - PG"),'Paste here'!AI11," -NA- ")) -> -NA- | AU11: =IF(OR(G11="TCPL",G11="PRACTICAL - UG",G11="PRACTICAL - PG"),'Paste here'!AL11," -NA- ") -> -NA- | AV11: =IF(OR(G11="TCPL",G11="PRACTICAL - UG",G11="PRACTICAL - PG"),'Paste here'!AK11," -NA- ") -> -NA- | AW11: =IF(OR(G11="TCPL",G11="PRACTICAL - UG",G11="PRACTICAL - PG"),"KRCE"," -NA- ") -> -NA- | AX11: =IF(OR(G11="TCPL",G11="PRACTICAL - UG",G11="PRACTICAL - PG"),'Paste here'!AJ11," -NA- ") -> -NA- | AY11: =IF(OR(G11="TCPL",G11="PRACTICAL - UG",G11="PRACTICAL - PG"),'Paste here'!M11," -NA- ") -> -NA- | AZ11: =IF(OR(G11="TCPL",G11="PRACTICAL - UG",G11="PRACTICAL - PG"),'Paste here'!N11," -NA- ") -> -NA- | BA11: =IF(OR(G11="TCPL",G11="PRACTICAL - UG",G11="PRACTICAL - PG"),Skilled!K11," -NA- ") -> -NA- | BB11: =IF(OR(G11="TCPL",G11="PRACTICAL - UG",G11="PRACTICAL - PG"),'Paste here'!AM11," -NA- ") -> -NA- | BC11: =UPPER(IF(OR(G11="TCPL",G11="PRACTICAL - UG",G11="PRACTICAL - PG"),'Paste here'!AN11," -NA- ")) -> -NA- | BD11: =UPPER(IF(OR(G11="TCPL",G11="PRACTICAL - UG",G11="PRACTICAL - PG"),'Paste here'!AO11," -NA- ")) -> -NA- | BE11: =UPPER(IF(OR(G11="TCPL",G11="PRACTICAL - UG",G11="PRACTICAL - PG"),'Paste here'!AP11," -NA- ")) -> -NA- | BF11: =IF(OR(G11="TCPL",G11="PRACTICAL - UG",G11="PRACTICAL - PG"),Skilled!L11,"") | BH11: =IF(OR(AG11="ENGLISH",AG11="MBA"),"",IF(OR(G11="PRACTICAL - UG",G11="PRACTICAL - PG"),'Paste here'!AQ11,"")) | BI11: =UPPER(IF(OR(G11="PRACTICAL - UG",G11="PRACTICAL - PG"),'Paste here'!AR11," -NA- ")) -> -NA- | BJ11: =IF(OR(G11="PRACTICAL - UG",G11="PRACTICAL - PG"),'Paste here'!AT11," -NA- ") -> -NA- | BK11: =IF(OR(AG11="ENGLISH",AG11="MBA"),"-NA-",IF(OR(G11="PRACTICAL - UG",G11="PRACTICAL - PG"),"KRCE"," -NA- ")) -> -NA- | BL11: =IF(OR(G11="PRACTICAL - UG",G11="PRACTICAL - PG"),'Paste here'!AS11," -NA- ") -> -NA- | BM11: =IF(OR(G11="PRACTICAL - UG",G11="PRACTICAL - PG"),'Paste here'!M11," -NA- ") -> -NA- | BN11: =IF(OR(G11="PRACTICAL - UG",G11="PRACTICAL - PG"),'Paste here'!N11," -NA- ") -> -NA- | BO11: =IF(OR(AG11="ENGLISH",AG11="MBA"),"",IF(OR(G11="PRACTICAL - UG",G11="PRACTICAL - PG"),Technician!J11," -NA- ")) -> -NA- | BP11: =IF(OR(G11="PRACTICAL - UG",G11="PRACTICAL - PG"),'Paste here'!AU11," -NA- ") -> -NA- | BQ11: =UPPER(IF(OR(,G11="PRACTICAL - UG",G11="PRACTICAL - PG"),'Paste here'!AV11," -NA- ")) -> -NA- | BR11: =UPPER(IF(OR(G11="PRACTICAL - UG",G11="PRACTICAL - PG"),'Paste here'!AW11," -NA- ")) -> -NA- | BS11: =UPPER(IF(OR(G11="PRACTICAL - UG",G11="PRACTICAL - PG"),'Paste here'!AX11," -NA- ")) -> -NA- | BT11: =IF(OR(AG11="ENGLISH",AG11="MBA"),"",IF(OR(G11="PRACTICAL - UG",G11="PRACTICAL - PG"),Technician!L11,""))
A12: ='Paste here'!A12 -> 0 | B12: ='Paste here'!F12 -> 0 | C12: ='Paste here'!J12 -> 0 | D12: ='Paste here'!K12 -> 0 | E12: =UPPER('Paste here'!H12) | F12: ='Paste here'!I12 -> 0 | G12: ='Paste here'!G12 -> 0 | H12: ='Paste here'!D12 -> 0 | I12: ='Paste here'!E12 -> 0 | K12: ='Paste here'!O12 -> 0 | L12: =UPPER('Paste here'!P12) | M12: ='Paste here'!S12 -> 0 | N12: ='Paste here'!R12 -> 0 | O12: ='Paste here'!T12 -> 0 | P12: =IF(VLOOKUP(O12,'Distance matrix'!B$2:C$238,2,FALSE)<36,"<35",VLOOKUP(O12,'Distance matrix'!B$2:C$238,2,FALSE)) -> #N/A | Q12: ='Paste here'!Q12 -> 0 | R12: ='Paste here'!M12 -> 0 | S12: ='Paste here'!N12 -> 0 | T12: =External!K12 -> #N/A | U12: =External!M12 -> 0 | V12: =External!L12 -> 0 | W12: =External!N12 -> #N/A | X12: ='Paste here'!U12 -> 0 | Y12: =UPPER('Paste here'!V12) | Z12: =UPPER('Paste here'!W12) | AA12: =UPPER('Paste here'!X12) | AB12: =External!O12 -> #VALUE! | AD12: ='Paste here'!Y12 -> 0 | AE12: =UPPER('Paste here'!Z12) | AF12: ='Paste here'!AC12 -> 0 | AG12: ='Paste here'!AB12 -> 0 | AH12: KRCE | AI12: ='Paste here'!AA12 -> 0 | AJ12: ='Paste here'!M12 -> 0 | AK12: ='Paste here'!N12 -> 0 | AL12: =Internal!L12 -> #N/A | AM12: ='Paste here'!AD12 -> 0 | AN12: =UPPER('Paste here'!AE12) | AO12: =UPPER('Paste here'!AF12) | AP12: =UPPER('Paste here'!AG12) | AQ12: =Internal!M12 -> #VALUE! | AS12: =IF(OR(G12="TCPL",G12="PRACTICAL - UG",G12="PRACTICAL - PG"),'Paste here'!AH12,"") | AT12: =UPPER(IF(OR(G12="TCPL",G12="PRACTICAL - UG",G12="PRACTICAL - PG"),'Paste here'!AI12," -NA- ")) -> -NA- | AU12: =IF(OR(G12="TCPL",G12="PRACTICAL - UG",G12="PRACTICAL - PG"),'Paste here'!AL12," -NA- ") -> -NA- | AV12: =IF(OR(G12="TCPL",G12="PRACTICAL - UG",G12="PRACTICAL - PG"),'Paste here'!AK12," -NA- ") -> -NA- | AW12: =IF(OR(G12="TCPL",G12="PRACTICAL - UG",G12="PRACTICAL - PG"),"KRCE"," -NA- ") -> -NA- | AX12: =IF(OR(G12="TCPL",G12="PRACTICAL - UG",G12="PRACTICAL - PG"),'Paste here'!AJ12," -NA- ") -> -NA- | AY12: =IF(OR(G12="TCPL",G12="PRACTICAL - UG",G12="PRACTICAL - PG"),'Paste here'!M12," -NA- ") -> -NA- | AZ12: =IF(OR(G12="TCPL",G12="PRACTICAL - UG",G12="PRACTICAL - PG"),'Paste here'!N12," -NA- ") -> -NA- | BA12: =IF(OR(G12="TCPL",G12="PRACTICAL - UG",G12="PRACTICAL - PG"),Skilled!K12," -NA- ") -> -NA- | BB12: =IF(OR(G12="TCPL",G12="PRACTICAL - UG",G12="PRACTICAL - PG"),'Paste here'!AM12," -NA- ") -> -NA- | BC12: =UPPER(IF(OR(G12="TCPL",G12="PRACTICAL - UG",G12="PRACTICAL - PG"),'Paste here'!AN12," -NA- ")) -> -NA- | BD12: =UPPER(IF(OR(G12="TCPL",G12="PRACTICAL - UG",G12="PRACTICAL - PG"),'Paste here'!AO12," -NA- ")) -> -NA- | BE12: =UPPER(IF(OR(G12="TCPL",G12="PRACTICAL - UG",G12="PRACTICAL - PG"),'Paste here'!AP12," -NA- ")) -> -NA- | BF12: =IF(OR(G12="TCPL",G12="PRACTICAL - UG",G12="PRACTICAL - PG"),Skilled!L12,"") | BH12: =IF(OR(AG12="ENGLISH",AG12="MBA"),"",IF(OR(G12="PRACTICAL - UG",G12="PRACTICAL - PG"),'Paste here'!AQ12,"")) | BI12: =UPPER(IF(OR(G12="PRACTICAL - UG",G12="PRACTICAL - PG"),'Paste here'!AR12," -NA- ")) -> -NA- | BJ12: =IF(OR(G12="PRACTICAL - UG",G12="PRACTICAL - PG"),'Paste here'!AT12," -NA- ") -> -NA- | BK12: =IF(OR(AG12="ENGLISH",AG12="MBA"),"-NA-",IF(OR(G12="PRACTICAL - UG",G12="PRACTICAL - PG"),"KRCE"," -NA- ")) -> -NA- | BL12: =IF(OR(G12="PRACTICAL - UG",G12="PRACTICAL - PG"),'Paste here'!AS12," -NA- ") -> -NA- | BM12: =IF(OR(G12="PRACTICAL - UG",G12="PRACTICAL - PG"),'Paste here'!M12," -NA- ") -> -NA- | BN12: =IF(OR(G12="PRACTICAL - UG",G12="PRACTICAL - PG"),'Paste here'!N12," -NA- ") -> -NA- | BO12: =IF(OR(AG12="ENGLISH",AG12="MBA"),"",IF(OR(G12="PRACTICAL - UG",G12="PRACTICAL - PG"),Technician!J12," -NA- ")) -> -NA- | BP12: =IF(OR(G12="PRACTICAL - UG",G12="PRACTICAL - PG"),'Paste here'!AU12," -NA- ") -> -NA- | BQ12: =UPPER(IF(OR(,G12="PRACTICAL - UG",G12="PRACTICAL - PG"),'Paste here'!AV12," -NA- ")) -> -NA- | BR12: =UPPER(IF(OR(G12="PRACTICAL - UG",G12="PRACTICAL - PG"),'Paste here'!AW12," -NA- ")) -> -NA- | BS12: =UPPER(IF(OR(G12="PRACTICAL - UG",G12="PRACTICAL - PG"),'Paste here'!AX12," -NA- ")) -> -NA- | BT12: =IF(OR(AG12="ENGLISH",AG12="MBA"),"",IF(OR(G12="PRACTICAL - UG",G12="PRACTICAL - PG"),Technician!L12,""))
A13: ='Paste here'!A13 -> 0 | B13: ='Paste here'!F13 -> 0 | C13: ='Paste here'!J13 -> 0 | D13: ='Paste here'!K13 -> 0 | E13: =UPPER('Paste here'!H13) | F13: ='Paste here'!I13 -> 0 | G13: ='Paste here'!G13 -> 0 | H13: ='Paste here'!D13 -> 0 | I13: ='Paste here'!E13 -> 0 | K13: ='Paste here'!O13 -> 0 | L13: =UPPER('Paste here'!P13) | M13: ='Paste here'!S13 -> 0 | N13: ='Paste here'!R13 -> 0 | O13: ='Paste here'!T13 -> 0 | P13: =IF(VLOOKUP(O13,'Distance matrix'!B$2:C$238,2,FALSE)<36,"<35",VLOOKUP(O13,'Distance matrix'!B$2:C$238,2,FALSE)) -> #N/A | Q13: ='Paste here'!Q13 -> 0 | R13: ='Paste here'!M13 -> 0 | S13: ='Paste here'!N13 -> 0 | T13: =External!K13 -> #N/A | U13: =External!M13 -> 0 | V13: =External!L13 -> 0 | W13: =External!N13 -> #N/A | X13: ='Paste here'!U13 -> 0 | Y13: =UPPER('Paste here'!V13) | Z13: =UPPER('Paste here'!W13) | AA13: =UPPER('Paste here'!X13) | AB13: =External!O13 -> #VALUE! | AD13: ='Paste here'!Y13 -> 0 | AE13: =UPPER('Paste here'!Z13) | AF13: ='Paste here'!AC13 -> 0 | AG13: ='Paste here'!AB13 -> 0 | AH13: KRCE | AI13: ='Paste here'!AA13 -> 0 | AJ13: ='Paste here'!M13 -> 0 | AK13: ='Paste here'!N13 -> 0 | AL13: =Internal!L13 -> #N/A | AM13: ='Paste here'!AD13 -> 0 | AN13: =UPPER('Paste here'!AE13) | AO13: =UPPER('Paste here'!AF13) | AP13: =UPPER('Paste here'!AG13) | AQ13: =Internal!M13 -> #VALUE! | AS13: =IF(OR(G13="TCPL",G13="PRACTICAL - UG",G13="PRACTICAL - PG"),'Paste here'!AH13,"") | AT13: =UPPER(IF(OR(G13="TCPL",G13="PRACTICAL - UG",G13="PRACTICAL - PG"),'Paste here'!AI13," -NA- ")) -> -NA- | AU13: =IF(OR(G13="TCPL",G13="PRACTICAL - UG",G13="PRACTICAL - PG"),'Paste here'!AL13," -NA- ") -> -NA- | AV13: =IF(OR(G13="TCPL",G13="PRACTICAL - UG",G13="PRACTICAL - PG"),'Paste here'!AK13," -NA- ") -> -NA- | AW13: =IF(OR(G13="TCPL",G13="PRACTICAL - UG",G13="PRACTICAL - PG"),"KRCE"," -NA- ") -> -NA- | AX13: =IF(OR(G13="TCPL",G13="PRACTICAL - UG",G13="PRACTICAL - PG"),'Paste here'!AJ13," -NA- ") -> -NA- | AY13: =IF(OR(G13="TCPL",G13="PRACTICAL - UG",G13="PRACTICAL - PG"),'Paste here'!M13," -NA- ") -> -NA- | AZ13: =IF(OR(G13="TCPL",G13="PRACTICAL - UG",G13="PRACTICAL - PG"),'Paste here'!N13," -NA- ") -> -NA- | BA13: =IF(OR(G13="TCPL",G13="PRACTICAL - UG",G13="PRACTICAL - PG"),Skilled!K13," -NA- ") -> -NA- | BB13: =IF(OR(G13="TCPL",G13="PRACTICAL - UG",G13="PRACTICAL - PG"),'Paste here'!AM13," -NA- ") -> -NA- | BC13: =UPPER(IF(OR(G13="TCPL",G13="PRACTICAL - UG",G13="PRACTICAL - PG"),'Paste here'!AN13," -NA- ")) -> -NA- | BD13: =UPPER(IF(OR(G13="TCPL",G13="PRACTICAL - UG",G13="PRACTICAL - PG"),'Paste here'!AO13," -NA- ")) -> -NA- | BE13: =UPPER(IF(OR(G13="TCPL",G13="PRACTICAL - UG",G13="PRACTICAL - PG"),'Paste here'!AP13," -NA- ")) -> -NA- | BF13: =IF(OR(G13="TCPL",G13="PRACTICAL - UG",G13="PRACTICAL - PG"),Skilled!L13,"") | BH13: =IF(OR(AG13="ENGLISH",AG13="MBA"),"",IF(OR(G13="PRACTICAL - UG",G13="PRACTICAL - PG"),'Paste here'!AQ13,"")) | BI13: =UPPER(IF(OR(G13="PRACTICAL - UG",G13="PRACTICAL - PG"),'Paste here'!AR13," -NA- ")) -> -NA- | BJ13: =IF(OR(G13="PRACTICAL - UG",G13="PRACTICAL - PG"),'Paste here'!AT13," -NA- ") -> -NA- | BK13: =IF(OR(AG13="ENGLISH",AG13="MBA"),"-NA-",IF(OR(G13="PRACTICAL - UG",G13="PRACTICAL - PG"),"KRCE"," -NA- ")) -> -NA- | BL13: =IF(OR(G13="PRACTICAL - UG",G13="PRACTICAL - PG"),'Paste here'!AS13," -NA- ") -> -NA- | BM13: =IF(OR(G13="PRACTICAL - UG",G13="PRACTICAL - PG"),'Paste here'!M13," -NA- ") -> -NA- | BN13: =IF(OR(G13="PRACTICAL - UG",G13="PRACTICAL - PG"),'Paste here'!N13," -NA- ") -> -NA- | BO13: =IF(OR(AG13="ENGLISH",AG13="MBA"),"",IF(OR(G13="PRACTICAL - UG",G13="PRACTICAL - PG"),Technician!J13," -NA- ")) -> -NA- | BP13: =IF(OR(G13="PRACTICAL - UG",G13="PRACTICAL - PG"),'Paste here'!AU13," -NA- ") -> -NA- | BQ13: =UPPER(IF(OR(,G13="PRACTICAL - UG",G13="PRACTICAL - PG"),'Paste here'!AV13," -NA- ")) -> -NA- | BR13: =UPPER(IF(OR(G13="PRACTICAL - UG",G13="PRACTICAL - PG"),'Paste here'!AW13," -NA- ")) -> -NA- | BS13: =UPPER(IF(OR(G13="PRACTICAL - UG",G13="PRACTICAL - PG"),'Paste here'!AX13," -NA- ")) -> -NA- | BT13: =IF(OR(AG13="ENGLISH",AG13="MBA"),"",IF(OR(G13="PRACTICAL - UG",G13="PRACTICAL - PG"),Technician!L13,""))
... A43: ='Paste here'!A43 -> L48 | B43: ='Paste here'!F43 -> 0 | C43: ='Paste here'!J43 -> 0 | D43: ='Paste here'!K43 -> 0 | E43: =UPPER('Paste here'!H43) | F43: ='Paste here'!I43 -> 0 | G43: ='Paste here'!G43 -> 0 | H43: ='Paste here'!D43 -> 0 | I43: ='Paste here'!E43 -> 0 | K43: ='Paste here'!O43 -> 0 | L43: =UPPER('Paste here'!P43) | M43: ='Paste here'!S43 -> 0 | N43: ='Paste here'!R43 -> 0 | O43: ='Paste here'!T43 -> 0 | P43: =IF(VLOOKUP(O43,'Distance matrix'!B$2:C$238,2,FALSE)<36,"<35",VLOOKUP(O43,'Distance matrix'!B$2:C$238,2,FALSE)) -> #N/A | Q43: ='Paste here'!Q43 -> 0 | R43: ='Paste here'!M43 -> 0 | S43: ='Paste here'!N43 -> 0 | T43: =External!K43 -> #N/A | U43: =External!M43 -> 0 | V43: =External!L43 -> 0 | W43: =External!N43 -> #N/A | X43: ='Paste here'!U43 -> 0 | Y43: =UPPER('Paste here'!V43) | Z43: =UPPER('Paste here'!W43) | AA43: =UPPER('Paste here'!X43) | AB43: =External!O43 -> #VALUE! | AD43: ='Paste here'!Y43 -> 0 | AE43: =UPPER('Paste here'!Z43) | AF43: ='Paste here'!AC43 -> 0 | AG43: ='Paste here'!AB43 -> 0 | AH43: KRCE | AI43: ='Paste here'!AA43 -> 0 | AJ43: ='Paste here'!M43 -> 0 | AK43: ='Paste here'!N43 -> 0 | AL43: =Internal!L43 -> #N/A | AM43: ='Paste here'!AD43 -> 0 | AN43: =UPPER('Paste here'!AE43) | AO43: =UPPER('Paste here'!AF43) | AP43: =UPPER('Paste here'!AG43) | AQ43: =Internal!M43 -> #VALUE! | AS43: =IF(OR(G43="TCPL",G43="PRACTICAL - UG",G43="PRACTICAL - PG"),'Paste here'!AH43,"") | AT43: =UPPER(IF(OR(G43="TCPL",G43="PRACTICAL - UG",G43="PRACTICAL - PG"),'Paste here'!AI43," -NA- ")) -> -NA- | AU43: =IF(OR(G43="TCPL",G43="PRACTICAL - UG",G43="PRACTICAL - PG"),'Paste here'!AL43," -NA- ") -> -NA- | AV43: =IF(OR(G43="TCPL",G43="PRACTICAL - UG",G43="PRACTICAL - PG"),'Paste here'!AK43," -NA- ") -> -NA- | AW43: =IF(OR(G43="TCPL",G43="PRACTICAL - UG",G43="PRACTICAL - PG"),"KRCE"," -NA- ") -> -NA- | AX43: =IF(OR(G43="TCPL",G43="PRACTICAL - UG",G43="PRACTICAL - PG"),'Paste here'!AJ43," -NA- ") -> -NA- | AY43: =IF(OR(G43="TCPL",G43="PRACTICAL - UG",G43="PRACTICAL - PG"),'Paste here'!M43," -NA- ") -> -NA- | AZ43: =IF(OR(G43="TCPL",G43="PRACTICAL - UG",G43="PRACTICAL - PG"),'Paste here'!N43," -NA- ") -> -NA- | BA43: =IF(OR(G43="TCPL",G43="PRACTICAL - UG",G43="PRACTICAL - PG"),Skilled!K43," -NA- ") -> -NA- | BB43: =IF(OR(G43="TCPL",G43="PRACTICAL - UG",G43="PRACTICAL - PG"),'Paste here'!AM43," -NA- ") -> -NA- | BC43: =UPPER(IF(OR(G43="TCPL",G43="PRACTICAL - UG",G43="PRACTICAL - PG"),'Paste here'!AN43," -NA- ")) -> -NA- | BD43: =UPPER(IF(OR(G43="TCPL",G43="PRACTICAL - UG",G43="PRACTICAL - PG"),'Paste here'!AO43," -NA- ")) -> -NA- | BE43: =UPPER(IF(OR(G43="TCPL",G43="PRACTICAL - UG",G43="PRACTICAL - PG"),'Paste here'!AP43," -NA- ")) -> -NA- | BF43: =IF(OR(G43="TCPL",G43="PRACTICAL - UG",G43="PRACTICAL - PG"),Skilled!L43,"") | BH43: =IF(OR(AG43="ENGLISH",AG43="MBA"),"",IF(OR(G43="PRACTICAL - UG",G43="PRACTICAL - PG"),'Paste here'!AQ43,"")) | BI43: =UPPER(IF(OR(G43="PRACTICAL - UG",G43="PRACTICAL - PG"),'Paste here'!AR43," -NA- ")) -> -NA- | BJ43: =IF(OR(G43="PRACTICAL - UG",G43="PRACTICAL - PG"),'Paste here'!AT43," -NA- ") -> -NA- | BK43: =IF(OR(AG43="ENGLISH",AG43="MBA"),"-NA-",IF(OR(G43="PRACTICAL - UG",G43="PRACTICAL - PG"),"KRCE"," -NA- ")) -> -NA- | BL43: =IF(OR(G43="PRACTICAL - UG",G43="PRACTICAL - PG"),'Paste here'!AS43," -NA- ") -> -NA- | BM43: =IF(OR(G43="PRACTICAL - UG",G43="PRACTICAL - PG"),'Paste here'!M43," -NA- ") -> -NA- | BN43: =IF(OR(G43="PRACTICAL - UG",G43="PRACTICAL - PG"),'Paste here'!N43," -NA- ") -> -NA- | BO43: =IF(OR(AG43="ENGLISH",AG43="MBA"),"",IF(OR(G43="PRACTICAL - UG",G43="PRACTICAL - PG"),Technician!J43," -NA- ")) -> -NA- | BP43: =IF(OR(G43="PRACTICAL - UG",G43="PRACTICAL - PG"),'Paste here'!AU43," -NA- ") -> -NA- | BQ43: =UPPER(IF(OR(,G43="PRACTICAL - UG",G43="PRACTICAL - PG"),'Paste here'!AV43," -NA- ")) -> -NA- | BR43: =UPPER(IF(OR(G43="PRACTICAL - UG",G43="PRACTICAL - PG"),'Paste here'!AW43," -NA- ")) -> -NA- | BS43: =UPPER(IF(OR(G43="PRACTICAL - UG",G43="PRACTICAL - PG"),'Paste here'!AX43," -NA- ")) -> -NA- | BT43: =IF(OR(AG43="ENGLISH",AG43="MBA"),"",IF(OR(G43="PRACTICAL - UG",G43="PRACTICAL - PG"),Technician!L43,""))

Sheet External
A1: Sl.No. | B1: Position held | C1: Title | D1: Name of Examiner | E1: College | F1: Sessions attended | G1: student Degree | H1: Subject Type | I1: Ext. Examiner type | J1: Examined Count | K1: Claim Amount | L1: DA | M1: TA | N1: TOTAL
A2: L1 | B2: External Examiner | C2: ='Paste here'!O2 -> Mrs. | D2: ='Paste here'!P2 -> Ranjani U | E2: ='Paste here'!T2 -> MAM SCHOOL OF ENGINEERING (8121) | F2: ='Paste here'!E2 -> Only FN | G2: ='Paste here'!F2 -> UG | H2: ='Paste here'!G2 -> TCPL | I2: ='Paste here'!L2 -> Regular Lab | J2: ='Paste here'!N2 -> 22 | K2: =IF(J2*VLOOKUP(H2,'Claim Amount'!$B$3:$J$24,2,FALSE)<VLOOKUP(H2,'Claim Amount'!$B$3:$J$24,3,FALSE),VLOOKUP(H2,'Claim Amount'!$B$3:$J$24,3,FALSE),J2*VLOOKUP(H2,'Claim Amount'!$B$3:$J$24,2,FALSE)) -> 440 | L2: =IF(I2="Regular Lab",VLOOKUP(F2,'Claim Amount'!$B$3:$J$13,2,FALSE),0) -> 250 | M2: =IF(I2="Regular Lab",IF(VLOOKUP(External!E2,'Distance matrix'!$B$1:$C$310,2,FALSE)<36,150,16*VLOOKUP(External!E2,'Distance matrix'!$B$1:$C$310,2,FALSE)),0) -> 150 | N2: =K2+L2+M2 -> 840 | O2: {=[1]!SPELLNUMBER(N2)} -> Rupees Eight Hundred Fourty Only
A3: L2 | B3: External Examiner | C3: ='Paste here'!O3 -> 0 | D3: ='Paste here'!P3 -> 0 | E3: ='Paste here'!T3 -> 0 | F3: ='Paste here'!E3 -> 0 | G3: ='Paste here'!F3 -> 0 | H3: ='Paste here'!G3 -> 0 | I3: ='Paste here'!L3 -> 0 | J3: ='Paste here'!N3 -> 0 | K3: =IF(J3*VLOOKUP(H3,'Claim Amount'!$B$3:$J$24,2,FALSE)<VLOOKUP(H3,'Claim Amount'!$B$3:$J$24,3,FALSE),VLOOKUP(H3,'Claim Amount'!$B$3:$J$24,3,FALSE),J3*VLOOKUP(H3,'Claim Amount'!$B$3:$J$24,2,FALSE)) -> #N/A | L3: =IF(I3="Regular Lab",VLOOKUP(F3,'Claim Amount'!$B$3:$J$13,2,FALSE),0) -> 0 | M3: =IF(I3="Regular Lab",IF(VLOOKUP(External!E3,'Distance matrix'!$B$1:$C$310,2,FALSE)<36,150,16*VLOOKUP(External!E3,'Distance matrix'!$B$1:$C$310,2,FALSE)),0) -> 0 | N3: =K3+L3+M3 -> #N/A | O3: {=[1]!SPELLNUMBER(N3)} -> #VALUE!
A4: L3 | B4: External Examiner | C4: ='Paste here'!O4 -> 0 | D4: ='Paste here'!P4 -> 0 | E4: ='Paste here'!T4 -> 0 | F4: ='Paste here'!E4 -> 0 | G4: ='Paste here'!F4 -> 0 | H4: ='Paste here'!G4 -> 0 | I4: ='Paste here'!L4 -> 0 | J4: ='Paste here'!N4 -> 0 | K4: =IF(J4*VLOOKUP(H4,'Claim Amount'!$B$3:$J$24,2,FALSE)<VLOOKUP(H4,'Claim Amount'!$B$3:$J$24,3,FALSE),VLOOKUP(H4,'Claim Amount'!$B$3:$J$24,3,FALSE),J4*VLOOKUP(H4,'Claim Amount'!$B$3:$J$24,2,FALSE)) -> #N/A | L4: =IF(I4="Regular Lab",VLOOKUP(F4,'Claim Amount'!$B$3:$J$13,2,FALSE),0) -> 0 | M4: =IF(I4="Regular Lab",IF(VLOOKUP(External!E4,'Distance matrix'!$B$1:$C$310,2,FALSE)<36,150,16*VLOOKUP(External!E4,'Distance matrix'!$B$1:$C$310,2,FALSE)),0) -> 0 | N4: =K4+L4+M4 -> #N/A | O4: {=[1]!SPELLNUMBER(N4)} -> #VALUE!
